Traceback (most recent call last):
  File "/home/test/.pyenv/versions/3.10.4/lib/python3.10/runpy.py", line 196, in _run_module_as_main
    return _run_code(code, main_globals, None,
  File "/home/test/.pyenv/versions/3.10.4/lib/python3.10/runpy.py", line 86, in _run_code
    exec(code, run_globals)
  File "/home/test/.vscode-server/extensions/ms-python.python-2023.20.0/pythonFiles/lib/python/debugpy/adapter/../../debugpy/launcher/__main__.py", line 91, in <module>
    main()
  File "/home/test/.vscode-server/extensions/ms-python.python-2023.20.0/pythonFiles/lib/python/debugpy/adapter/../../debugpy/launcher/__main__.py", line 47, in main
    launcher.connect(host, port)
  File "/home/test/.vscode-server/extensions/ms-python.python-2023.20.0/pythonFiles/lib/python/debugpy/adapter/../../debugpy/launcher/../../debugpy/launcher/__init__.py", line 27, in connect
    sock.connect((host, port))
ConnectionRefusedError: [Errno 111] Connection refused
Traceback (most recent call last):
  File "/home/test/.pyenv/versions/3.10.4/lib/python3.10/runpy.py", line 196, in _run_module_as_main
    return _run_code(code, main_globals, None,
  File "/home/test/.pyenv/versions/3.10.4/lib/python3.10/runpy.py", line 86, in _run_code
    exec(code, run_globals)
  File "/home/test/.vscode-server/extensions/ms-python.python-2023.20.0/pythonFiles/lib/python/debugpy/adapter/../../debugpy/launcher/__main__.py", line 91, in <module>
    main()
  File "/home/test/.vscode-server/extensions/ms-python.python-2023.20.0/pythonFiles/lib/python/debugpy/adapter/../../debugpy/launcher/__main__.py", line 47, in main
    launcher.connect(host, port)
  File "/home/test/.vscode-server/extensions/ms-python.python-2023.20.0/pythonFiles/lib/python/debugpy/adapter/../../debugpy/launcher/../../debugpy/launcher/__init__.py", line 27, in connect
    sock.connect((host, port))
ConnectionRefusedError: [Errno 111] Connection refused
